2016-01-22 13:45:41,530 [Thread-285:41944] [logger:40] [DEBUG]- [user login] luozh login ok.
2016-01-22 13:54:14,687 [Thread-461:39104] [logger:40] [DEBUG]- [user login] luozh login ok.
2016-01-22 14:04:58,443 [Thread-1038:36492] [logger:40] [DEBUG]- [user login] luozh login ok.
2016-01-22 14:24:34,259 [Thread-1732:31444] [logger:41] [ERROR]- Traceback (most recent call last):
  File "D:\work\Aptana Studio 3 Workspace\ujobs\source\ujobs\page\timing_manage.py", line 38, in timing_manage_list
    logger.debug("current job status: {0}".format(scheduler.print_jobs()))
  File "C:\Python27\lib\site-packages\apscheduler\schedulers\base.py", line 555, in print_jobs
    jobs = store.get_all_jobs()
  File "C:\Python27\lib\site-packages\apscheduler\jobstores\sqlalchemy.py", line 73, in get_all_jobs
    jobs = self._get_jobs()
  File "C:\Python27\lib\site-packages\apscheduler\jobstores\sqlalchemy.py", line 124, in _get_jobs
    for row in self.engine.execute(selectable):
  File "C:\Python27\lib\site-packages\sqlalchemy\engine\base.py", line 1991, in execute
    return connection.execute(statement, *multiparams, **params)
  File "C:\Python27\lib\site-packages\sqlalchemy\engine\base.py", line 914, in execute
    return meth(self, multiparams, params)
  File "C:\Python27\lib\site-packages\sqlalchemy\sql\elements.py", line 323, in _execute_on_connection
    return connection._execute_clauseelement(self, multiparams, params)
  File "C:\Python27\lib\site-packages\sqlalchemy\engine\base.py", line 1010, in _execute_clauseelement
    compiled_sql, distilled_params
  File "C:\Python27\lib\site-packages\sqlalchemy\engine\base.py", line 1146, in _execute_context
    context)
  File "C:\Python27\lib\site-packages\sqlalchemy\engine\base.py", line 1341, in _handle_dbapi_exception
    exc_info
  File "C:\Python27\lib\site-packages\sqlalchemy\util\compat.py", line 199, in raise_from_cause
    reraise(type(exception), exception, tb=exc_tb)
  File "C:\Python27\lib\site-packages\sqlalchemy\engine\base.py", line 1139, in _execute_context
    context)
  File "C:\Python27\lib\site-packages\sqlalchemy\engine\default.py", line 450, in do_execute
    cursor.execute(statement, parameters)
  File "C:\Python27\lib\site-packages\MySQLdb\cursors.py", line 205, in execute
    self.errorhandler(self, exc, value)
  File "C:\Python27\lib\site-packages\MySQLdb\connections.py", line 36, in defaulterrorhandler
    raise errorclass, errorvalue
OperationalError: (_mysql_exceptions.OperationalError) (2006, 'MySQL server has gone away') [SQL: u'SELECT apscheduler_jobs.id, apscheduler_jobs.job_state \nFROM apscheduler_jobs ORDER BY apscheduler_jobs.next_run_time']

2016-01-22 15:25:13,963 [Thread-2032:26344] [logger:38] [DEBUG]- current job status: None
2016-01-22 17:09:26,086 [Thread-2062:29500] [logger:40] [DEBUG]- [user login] luozh login ok.
